Workbook

Sheet README
A1: Family Income Statement 2026 — v4
A3: TABS:
A4: README — this guide
A5: Income Statement — main monthly P&L
A6: CC Detail — categorized variable spending (auto)
A7: Solar ROI — capital, monthly savings, payback
A8: Balances — month-end account snapshots
A9: Comp & Benefits — Matt 401k, Sue pension/403b, FSA tracking
A10: Scenarios — financial what-if analysis
A11: Charts — auto-generated charts (run from menu)
A12: Imports - Checking / Savings / Barclay — paste raw CSVs here
A13: Rules — merchant -> category mappings
... A91: Green number = positive / good variance

Sheet Income Statement
A1: Family Income Statement — 2026
A2: Yellow = enter values. White = formulas. Some lines pull from CC Detail or Solar ROI.
A4: Category | B4: Jan | C4: Feb | D4: Mar | E4: Apr | F4: May | G4: Jun | H4: Jul | I4: Aug | J4: Sep | K4: Oct | L4: Nov | M4: Dec | N4: YTD Total | O4: Avg/mo
A6: INCOME
A7: Sue — net pay (Town of Sharon) | B7: 6470.41 | C7: 6627.84 | D7: 6470.42 | E7: 9705.26 | F7: 6526.38 | N7: =SUM(B7:M7) -> 35800.31 | O7: =IFERROR(AVERAGEIF(B7:M7,"<>0"),0) -> 7160.062
A8: Matt — net pay (MathWorks) | B8: 5179.07 | C8: 4551.25 | D8: 3827.99 | E8: 5427.48 | F8: 5989.44 | N8: =SUM(B8:M8) -> 24975.23 | O8: =IFERROR(AVERAGEIF(B8:M8,"<>0"),0) -> 4995.046
A9: Q4 stakeholder bonus (MW lump, doubled) | N9: =SUM(B9:M9) -> 0 | O9: =IFERROR(AVERAGEIF(B9:M9,"<>0"),0) -> 0
A10: Interest earned | B10: 155.3 | C10: 144.4 | D10: 87.26 | E10: 94.93 | F10: 79.5 | N10: =SUM(B10:M10) -> 561.39 | O10: =IFERROR(AVERAGEIF(B10:M10,"<>0"),0) -> 112.278
A11: FSA Dep Care reimbursement (lump from Wex) | N11: =SUM(B11:M11) -> 0 | O11: =IFERROR(AVERAGEIF(B11:M11,"<>0"),0) -> 0
A12: Tuition reimbursement (MathWorks) | N12: =SUM(B12:M12) -> 0 | O12: =IFERROR(AVERAGEIF(B12:M12,"<>0"),0) -> 0
A13: Tax refunds (Federal/MA) | E13: 603 | N13: =SUM(B13:M13) -> 603 | O13: =IFERROR(AVERAGEIF(B13:M13,"<>0"),0) -> 603
A14: CC rewards / Misc refunds / Side income | B14: 72.01 | C14: 77.53 | D14: 43.52 | E14: 209.21 | F14: 177.6 | G14: 90.95 | N14: =SUM(B14:M14) -> 670.82 | O14: =IFERROR(AVERAGEIF(B14:M14,"<>0"),0) -> 111.80333
A15: Total Income | B15: =SUM(B7:B14) -> 11876.79 | C15: =SUM(C7:C14) -> 11401.02 | D15: =SUM(D7:D14) -> 10429.19 | E15: =SUM(E7:E14) -> 16039.88 | F15: =SUM(F7:F14) -> 12772.92 | G15: =SUM(G7:G14) -> 90.95 | H15: =SUM(H7:H14) -> 0 | I15: =SUM(I7:I14) -> 0 | ... N15: =SUM(N7:N14) -> 62610.75 | O15: =IFERROR(N15/COUNTIF(B15:M15,">0"),0) -> 10435.125
A17: FIXED EXPENSES
A18: Mortgage (Rocket biweekly avg) | B18: 3288.58 | C18: 3288.58 | D18: 3288.58 | E18: 3288.58 | F18: 3288.58 | N18: =SUM(B18:M18) -> 16442.9 | O18: =IFERROR(AVERAGEIF(B18:M18,"<>0"),0) -> 3288.58
A19: Car — 2023 Sienna loan (BoA) | B19: 384 | C19: 384 | D19: 576 | E19: 384 | F19: 384 | N19: =SUM(B19:M19) -> 2112 | O19: =IFERROR(AVERAGEIF(B19:M19,"<>0"),0) -> 422.4
A20: Car — 2022 RAV4 loan (Toyota) | B20: 416 | C20: 416 | D20: 624 | E20: 416 | F20: 416 | N20: =SUM(B20:M20) -> 2288 | O20: =IFERROR(AVERAGEIF(B20:M20,"<>0"),0) -> 457.6
A21: Childcare (checks) | B21: 724.6 | C21: 684.34 | E21: 1229.2 | F21: 421.6 | N21: =SUM(B21:M21) -> 3059.74 | O21: =IFERROR(AVERAGEIF(B21:M21,"<>0"),0) -> 764.935
A22: Tuition (Northeastern) | E22: 1848.3 | N22: =SUM(B22:M22) -> 1848.3 | O22: =IFERROR(AVERAGEIF(B22:M22,"<>0"),0) -> 1848.3
A23: Life insurance — American General | B23: 46.19 | C23: 46.19 | D23: 46.19 | E23: 46.19 | F23: 46.19 | N23: =SUM(B23:M23) -> 230.95 | O23: =IFERROR(AVERAGEIF(B23:M23,"<>0"),0) -> 46.19
A24: Life insurance — ALIC | C24: 90.39 | D24: 90.39 | E24: 90.39 | F24: 90.39 | N24: =SUM(B24:M24) -> 361.56 | O24: =IFERROR(AVERAGEIF(B24:M24,"<>0"),0) -> 90.39
A25: Verizon | B25: 54.99 | C25: 54.99 | D25: 54.99 | E25: 54.99 | F25: 54.99 | N25: =SUM(B25:M25) -> 274.95 | O25: =IFERROR(AVERAGEIF(B25:M25,"<>0"),0) -> 54.99
A26: T-Mobile | B26: 138.05 | C26: 139.64 | D26: 139.64 | E26: 139.61 | F26: 139.61 | N26: =SUM(B26:M26) -> 696.55 | O26: =IFERROR(AVERAGEIF(B26:M26,"<>0"),0) -> 139.31
A27: Schwab investment (529) | B27: 100 | D27: 200 | E27: 100 | N27: =SUM(B27:M27) -> 400 | O27: =IFERROR(AVERAGEIF(B27:M27,"<>0"),0) -> 133.33333
A28: Fidelity investment ($50/mo) | B28: 100 | C28: 50 | D28: 200 | E28: 100 | G28: 100 | N28: =SUM(B28:M28) -> 550 | O28: =IFERROR(AVERAGEIF(B28:M28,"<>0"),0) -> 110
A29: Total Fixed Expenses | B29: 50 | C29: 50 | D29: 50 | E29: 50 | F29: 50 | G29: 100 | H29: 0 | I29: 0 | J29: 0 | K29: 0 | L29: 0 | M29: 0 | N29: =SUM(N18:N28) -> 28264.95 | O29: =IFERROR(N29/COUNTIF(B29:M29,">0"),0) -> 4710.825
A31: UTILITIES (Gas/Electric Currently Lumped)
A32: Gas bill | B32: 508.66 | C32: 528.66 | D32: 637 | E32: 405.83 | F32: 303.96 | G32: 223.28 | N32: =SUM(B32:M32) -> 2607.39 | O32: =IFERROR(AVERAGEIF(B32:M32,"<>0"),0) -> 434.565
A33: Electric (Eversource — pre-solar) | B33: 189.8 | C33: 364.31 | D33: 351.64 | E33: 207.68 | F33: 194.51 | G33: 87 | N33: =SUM(B33:M33) -> 1394.94 | O33: =IFERROR(AVERAGEIF(B33:M33,"<>0"),0) -> 232.49
A34: Water | N34: =SUM(B34:M34) -> 0 | O34: =IFERROR(AVERAGEIF(B34:M34,"<>0"),0) -> 0
A35: Total Utilities | B35: =SUM(B32:B34) -> 698.46 | C35: =SUM(C32:C34) -> 892.97 | D35: =SUM(D32:D34) -> 988.64 | E35: =SUM(E32:E34) -> 613.51 | F35: =SUM(F32:F34) -> 498.47 | G35: =SUM(G32:G34) -> 310.28 | H35: =SUM(H32:H34) -> 0 | I35: =SUM(I32:I34) -> 0 | ... N35: =SUM(N32:N34) -> 4002.33 | O35: =IFERROR(N35/COUNTIF(B35:M35,">0"),0) -> 667.055
A37: VARIABLE SPENDING (auto-pulled from CC Detail)
A38: Groceries | B38: 635.4 | C38: 940.29 | D38: 701.42 | E38: 720.34 | F38: 427.34 | N38: =SUM(B38:M38) -> 3424.79 | O38: =IFERROR(AVERAGEIF(B38:M38,"<>0"),0) -> 684.958
A39: Gas / Vehicle | B39: 198.77 | C39: 242.84 | D39: 214.4 | E39: 356.42 | F39: 302.96 | N39: =SUM(B39:M39) -> 1315.39 | O39: =IFERROR(AVERAGEIF(B39:M39,"<>0"),0) -> 263.078
A40: Dining out | B40: 683.65 | C40: 884.87 | D40: 575 | E40: 1032.83 | F40: 427.35 | N40: =SUM(B40:M40) -> 3603.7 | O40: =IFERROR(AVERAGEIF(B40:M40,"<>0"),0) -> 720.74
A41: Subscriptions | B41: 111.05 | C41: 104.34 | D41: 111.05 | E41: 160.4 | F41: 153.07 | N41: =SUM(B41:M41) -> 639.91 | O41: =IFERROR(AVERAGEIF(B41:M41,"<>0"),0) -> 127.982
A42: Kids / Activities | B42: 240 | C42: 27 | D42: 90 | E42: 490.32 | F42: 654.24 | N42: =SUM(B42:M42) -> 1501.56 | O42: =IFERROR(AVERAGEIF(B42:M42,"<>0"),0) -> 300.312
A43: Travel | D43: 30.54 | E43: 917.41 | F43: 104.8 | N43: =SUM(B43:M43) -> 1052.75 | O43: =IFERROR(AVERAGEIF(B43:M43,"<>0"),0) -> 350.91667
A44: Personal Care | B44: 53.5 | C44: 1.44 | D44: 215.5 | E44: 96.53 | F44: 335.47 | N44: =SUM(B44:M44) -> 702.44 | O44: =IFERROR(AVERAGEIF(B44:M44,"<>0"),0) -> 140.488
A45: Pharmacy / Health | B45: 35.54 | C45: 55.34 | D45: 18 | E45: 108.71 | F45: 8.72 | N45: =SUM(B45:M45) -> 226.31 | O45: =IFERROR(AVERAGEIF(B45:M45,"<>0"),0) -> 45.262
...

Sheet CC Detail
A1: Variable Spending — by category (auto-populated)
A2: Auto-regenerated by Apps Script. Edit Rules tab to change categorization rather than typing here directly.
A4: Category | B4: Jan | C4: Feb | D4: Mar | E4: Apr | F4: May | G4: Jun | H4: Jul | I4: Aug | J4: Sep | K4: Oct | L4: Nov | M4: Dec | N4: YTD
A5: Groceries | B5: 635.4 | C5: 940.29 | D5: 701.42 | E5: 746.33 | F5: 630.8 | G5: 146.28 | N5: =SUM(B5:M5) -> 3800.52
A6: Gas / Vehicle | B6: 198.77 | C6: 242.84 | D6: 214.4 | E6: 356.42 | F6: 530.1 | N6: =SUM(B6:M6) -> 1542.53
A7: Dining out | B7: 683.65 | C7: 884.87 | D7: 575 | E7: 1032.83 | F7: 935.71 | G7: 74.96 | N7: =SUM(B7:M7) -> 4187.02
A8: Subscriptions | B8: 111.05 | C8: 104.34 | D8: 111.05 | E8: 160.4 | F8: 154.06 | G8: 6.69 | N8: =SUM(B8:M8) -> 647.59
A9: Kids / Activities | B9: 240 | C9: 37.61 | D9: 128.26 | E9: 533.78 | F9: 677.24 | G9: 295.65 | N9: =SUM(B9:M9) -> 1912.54
A10: Travel | D10: 30.54 | E10: 917.41 | F10: 104.8 | N10: =SUM(B10:M10) -> 1052.75
A11: Personal Care | B11: 53.5 | C11: 1.44 | D11: 215.5 | E11: 96.53 | F11: 335.47 | G11: 100 | N11: =SUM(B11:M11) -> 802.44
A12: Pharmacy / Health | B12: 35.54 | C12: 55.34 | D12: 18 | E12: 108.71 | F12: 12.1 | G12: 3.79 | N12: =SUM(B12:M12) -> 233.48
A13: Home / Hardware | B13: 47.18 | C13: 186.05 | D13: 26.75 | E13: 224.72 | F13: 389.01 | G13: 123.82 | N13: =SUM(B13:M13) -> 997.53
A14: Amazon (misc) | B14: 856.77 | C14: 267.06 | D14: 417.23 | E14: 482.16 | F14: 688.51 | G14: 157.93 | N14: =SUM(B14:M14) -> 2869.66
A15: Landscaping | E15: 490 | F15: 75 | G15: 65 | N15: =SUM(B15:M15) -> 630
A16: Cash / allowances | F16: 600 | N16: =SUM(B16:M16) -> 600
A17: Other / misc | B17: 2349.16 | C17: 450.94 | D17: 24367.44 | E17: 1769.75 | F17: 3985.28 | G17: -2.22 | N17: =SUM(B17:M17) -> 32920.35
A18: Total variable spending | B18: =SUM(B5:B17) -> 5211.02 | C18: =SUM(C5:C17) -> 3170.78 | D18: =SUM(D5:D17) -> 26805.59 | E18: =SUM(E5:E17) -> 6919.04 | F18: =SUM(F5:F17) -> 9118.08 | G18: =SUM(G5:G17) -> 971.9 | H18: =SUM(H5:H17) -> 0 | I18: =SUM(I5:I17) -> 0 | ... N18: =SUM(N5:N17) -> 52196.41
A20: Barclaycard statement total (manual — sanity) | B20: 5863 | C20: 5466 | D20: 3914 | E20: 8658 | F20: 4911 | N20: =SUM(B20:M20) -> 28812
A21: (Categorized − Statement) — should be ~0 | B21: =B18-B20 -> -651.98 | C21: =C18-C20 -> -2295.22 | D21: =D18-D20 -> 22891.59 | E21: =E18-E20 -> -1738.96 | F21: =F18-F20 -> 4207.08 | G21: =G18-G20 -> 971.9 | H21: =H18-H20 -> 0 | I21: =I18-I20 -> 0 | ... N21: =N18-N20 -> 23384.41

Sheet Solar ROI
A1: Solar Panel ROI Tracker
A2: Capital costs in row 5. Net meter goes live: track baseline (what you would have paid) vs. actual (with solar).
A4: Item | B4: Jan | C4: Feb | D4: Mar | E4: Apr | F4: May | G4: Jun | H4: Jul | I4: Aug | J4: Sep | K4: Oct | L4: Nov | M4: Dec | N4: YTD
A5: Capital outlay | B5: 5000 | D5: 26318 | F5: 2000 | N5: =SUM(B5:M5) -> 33318
A6: Tax credits / incentives | N6: =SUM(B6:M6) -> 0
A7: Net capital cost | N7: =N5-N6 -> 33318
A9: Baseline electric (estimate) | G9: 143 | H9: 206.98 | I9: 308.95 | N9: =SUM(B9:M9) -> 658.93
A10: Actual electric bill | G10: 87 | H10: 105.09 | I10: 122.29 | N10: =SUM(B10:M10) -> 314.38
A11: Monthly savings | B11: =B9-B10 -> 0 | C11: =C9-C10 -> 0 | D11: =D9-D10 -> 0 | E11: =E9-E10 -> 0 | F11: =F9-F10 -> 0 | G11: =G9-G10 -> 56 | H11: =H9-H10 -> 101.89 | I11: =I9-I10 -> 186.66 | ... M11: =M9-M10 -> 0 | N11: =SUM(B11:M11) -> 344.55
A12: Cumulative savings | B12: =B11 -> 0 | C12: =B12+C11 -> 0 | D12: =C12+D11 -> 0 | E12: =D12+E11 -> 0 | F12: =E12+F11 -> 0 | G12: =F12+G11 -> 56 | H12: =G12+H11 -> 157.89 | I12: =H12+I11 -> 344.55 | J12: =I12+J11 -> 344.55 | ... M12: =L12+M11 -> 344.55
A14: Payback summary
A15: Net capital cost | B15: =N7 -> 33318
A16: Avg monthly savings | B16: =IFERROR(AVERAGEIF(B11:M11,"<>0"),0) -> 114.85
A17: Projected annual savings | B17: =B16*12 -> 1378.2
A18: Payback period (years) | B18: =IFERROR(B15/B17,"-") -> 24.175011
A19: % paid back | B19: =IFERROR(N12/B15,0) -> 0
A21: ⚠ Incentives (row 6): the 30% federal solar credit (25D) ended for systems placed in service after 12/31/2025 (OBBB, 7/4/2025); yours went live ~Apr 2026, so federal = $0. MA still gives a 15% state credit up to $1,000. Full reinvestment model on the 'Solar Reinvestment' tab →
A24: Real data entered for the first clean post-solar months (Jun–Aug): baseline = 2025 same-month bills, actual = 2026 bills → saved ~$56 / $102 / $187. 2026 winter bills spiked on rates & cold, so earlier months aren't a clean solar comparison — add post-solar winter data (Nov 2026+) for a full-year payback.

Sheet Balances
A1: Account Balances — month-end snapshots
A2: Snapshot at end of each month.
A4: Account | B4: Jan | C4: Feb | D4: Mar | E4: Apr | F4: May | G4: Jun | H4: Jul | I4: Aug | J4: Sep | K4: Oct | L4: Nov | M4: Dec
A5: Capital One Checking (7912)
A6: Capital One Savings (8940) | F6: 28188.03
A7: Capital One Venmo float (9345) | F7: 75 | G7: 26
A8: Fidelity Money Market | F8: 2929
A9: Schwab investment
A10: 529 | F10: 14298
A11: FSA Dep Care balance
A12: FSA Health Care balance
A13: Matt 401k (MathWorks) | F13: 228000
A14: Sue 403b (Equitable)
A15: Sue pension (estimated)
A16: Other
A17: Total assets | B17: =SUM(B5:B16) -> 0 | C17: =SUM(C5:C16) -> 0 | D17: =SUM(D5:D16) -> 0 | E17: =SUM(E5:E16) -> 0 | F17: =SUM(F5:F16) -> 273490.03 | G17: =SUM(G5:G16) -> 26 | H17: =SUM(H5:H16) -> 0 | I17: =SUM(I5:I16) -> 0 | ... M17: =SUM(M5:M16) -> 0
A18: MoM change (assets) | C18: =IF(B17=0,0,C17-B17) -> 0 | D18: =IF(C17=0,0,D17-C17) -> 0 | E18: =IF(D17=0,0,E17-D17) -> 0 | F18: =IF(E17=0,0,F17-E17) -> 0 | G18: =IF(F17=0,0,G17-F17) -> -273464.03 | H18: =IF(G17=0,0,H17-G17) -> -26 | I18: =IF(H17=0,0,I17-H17) -> 0 | J18: =IF(I17=0,0,J17-I17) -> 0 | ... M18: =IF(L17=0,0,M17-L17) -> 0

Sheet Comp & Benefits
A1: Compensation & Benefits Tracking
A2: Track YTD progress on retirement contributions, FSA, employer match. Update from paystubs (or from Workday/MathWorks portal monthly).
A4: MATT (MathWorks)
A5: Item | B5: Per pay period | C5: YTD | D5: Annual cap (2026) | E5: % used | F5: Notes
A6: Gross earnings | C6: 41980 | F6: Hourly + OT + Stakeholder + Reimbursements YTD
A7: Contribution rate % | B7: 0.23 | D7: 50% cap | F7: Auto-increases 1%/yr on May 1 up to 50% cap
A8: 401k contribution (target) | C8: 8794.41 | D8: 23500 | F8: 22% of ~$144k = ~$31,800 intended; PLAN AUTO-CAPS at $23,500. Maxes out by ~Sep.
A9: 401k match (3% baseline, throughout) | B9: 109.92 | C9: 1249.83 | D9: 4338 | F9: MW matches first 3% of pay; calculated as 3% of $144,612
A10: 401k match Q4 true-up (3% lump) | C10: 3164 | D10: 4338 | F10: MW typically doubles to 6% at year-end (lump in 401k acct, NOT cash)
A11: FSA Dep Care | B11: 153.85 | C11: 1538.5 | D11: 4000 | E11: =C11/D11 -> 0.384625 | F11: Reimbursed when receipts submitted
A12: FSA Health Care | B12: 96.15 | C12: 961.5 | D12: 3300 | E12: =C12/D12 -> 0.29136364 | F12: 2026 limit; reimbursed for medical expenses
A13: Tuition reimbursement (received) | C13: 3634 | D13: 5250 | E13: =C13/D13 -> 0.69219048 | F13: IRC §127 tax-free up to $5,250/yr
A14: Stakeholder Earnings YTD | C14: 2964.21 | F14: Doubled in Q4 — track when received
A15: Q4 stakeholder bonus | F15: Lump sum, hits checking separately
A17: SUE (Sharon Public Schools)
A18: Item | B18: Per pay period | C18: YTD | D18: Annual cap (2026) | E18: % used | F18: Notes
A19: MA pension contribution | F19: Mandatory deduction; not in retirement portfolio
A20: 403b contribution (Equitable) | B20: 0 | C20: 0 | D20: 23500 | E20: 0 | F20: STOPPED — high fees; consider restart + annual rollover to Fidelity
A21: 403b match | F21: Verify if district matches — depends on contract
A22: Total retirement % | F22: Track total Sue retirement savings rate including pension
A24: 529 (kids college)
A25: Item | B25: Per month | C25: YTD | D25: MA tax deduction cap | E25: % used | F25: Notes
A26: 529 contributions | B26: 100 | C26: =B26*5 -> 500 | D26: 2000 | E26: =C26/D26 -> 0.25 | F26: MA deducts up to $2k joint (~$100/yr tax savings)

Sheet Scenarios
A1: Financial Scenarios — what-if analysis
A2: Orange cells = inputs you can change. Other cells calculate automatically. Models 20-year horizon with simplified assumptions — not investment advice.
A4: ASSUMPTIONS
A5: Expected investment return (annual) | B5: 0.07 | C5: Stock/bond mix typical for retirement timeline
A6: Time horizon (years) | B6: 20
A7: MA marginal tax rate | B7: 0.05
A8: Federal marginal tax rate | B8: 0.22
A10: LOANS
A11: Loan | B11: Balance | C11: Rate | D11: Monthly pmt | E11: Months left | F11: Interest remaining
A12: RAV4 (Toyota) | B12: 0 | C12: 0 | D12: 0 | E12: 0 | F12: =D12*E12-B12 -> 0
A13: Sienna (BoA) | B13: 14374 | C13: 0.0635 | D13: 384.16 | E13: 48 | F13: =D13*E13-B13 -> 4065.68
A14: Mortgage (Rocket) | B14: 350000 | C14: 0.0575 | D14: 3289 | E14: 320 | F14: =D14*E14-B14 -> 702480
A16: SCENARIOS — projected outcomes over horizon
A17: Action | B17: Status quo | C17: Restart Sue 403b at $300/mo | D17: Pay off RAV4 → backdoor Roth IRAs ($7k×2) | E17: Pay off RAV4 + restart Sue 403b | F17: Aggressive: all above + boost 529 to $300/mo
A18: Monthly cash impact (vs status quo) | B18: 0 | C18: =-300 -> -300 | D18: =451-1167 -> -716 | E18: =451-300 -> 151 | F18: =451-1167-300-200 -> -1216
A19: New annual investment contributions | B19: 0 | C19: =300*12 -> 3600 | D19: =14000 -> 14000 | E19: =300*12 -> 3600 | F19: =300*12+14000+200*12 -> 20000
A20: Annual tax savings (federal+state) | B20: 0 | C20: =300*12*($B$8+$B$7) -> 972 | D20: =0 -> 0 | E20: =300*12*($B$8+$B$7) -> 972 | F20: =300*12*($B$8+$B$7)+MIN(200*12,2000)*$B$7 -> 1072
A21: Loan interest saved (one-time) | B21: 0 | C21: =0 -> 0 | D21: =F12 -> 0 | E21: =F12 -> 0 | F21: =F12 -> 0
A22: Investment growth over horizon | B22: 0 | C22: =300*((((1+$B$5/12)^($B$6*12))-1)/($B$5/12)) -> 156278 | D22: =(14000/12)*((((1+$B$5/12)^($B$6*12))-1)/($B$5/12)) -> 607747.77 | E22: =300*((((1+$B$5/12)^($B$6*12))-1)/($B$5/12)) -> 156278 | F22: =(300+200)*((((1+$B$5/12)^($B$6*12))-1)/($B$5/12))+(14000/12)*((((1+$B$5/12)^($B$6*12))-1)/($B$5/12)) -> 868211.1
A23: TOTAL benefit (FV + interest saved + tax savings × horizon) | B23: =B22+B21+B20*$B$6 -> 0 | C23: =C22+C21+C20*$B$6 -> 175718 | D23: =D22+D21+D20*$B$6 -> 607747.77 | E23: =E22+E21+E20*$B$6 -> 175718 | F23: =F22+F21+F20*$B$6 -> 889651.1

Sheet Charts
A1: Charts (auto-generated)
A2: Run: 📊 Family Finances → Generate / Refresh Charts. The Apps Script creates 4 charts on this tab from the data in Income Statement, CC Detail, Solar ROI, and Balances tabs.
A4: Cash Flow Summary (auto)
A5: Month | B5: Jan | C5: Feb | D5: Mar | E5: Apr | F5: May | G5: Jun | H5: Jul | I5: Aug | J5: Sep | K5: Oct | L5: Nov | M5: Dec
A6: Total Income | B6: ='Income Statement'!B15 -> 11876.79 | C6: ='Income Statement'!C15 -> 11401.02 | D6: ='Income Statement'!D15 -> 10429.19 | E6: ='Income Statement'!E15 -> 16039.88 | F6: ='Income Statement'!F15 -> 12772.92 | G6: ='Income Statement'!G15 -> 90.95 | H6: ='Income Statement'!H15 -> 0 | I6: ='Income Statement'!I15 -> 0 | ... M6: ='Income Statement'!M15 -> 0
A7: Total Expenses | B7: ='Income Statement'!B61 -> 0 | C7: ='Income Statement'!C61 -> 0 | D7: ='Income Statement'!D61 -> 0 | E7: ='Income Statement'!E61 -> 0 | F7: ='Income Statement'!F61 -> 0 | G7: ='Income Statement'!G61 -> 0 | H7: ='Income Statement'!H61 -> 0 | I7: ='Income Statement'!I61 -> 0 | ... M7: ='Income Statement'!M61 -> 0
A8: Net Cash Flow | B8: ='Income Statement'!B63 -> 0 | C8: ='Income Statement'!C63 -> 0 | D8: ='Income Statement'!D63 -> 0 | E8: ='Income Statement'!E63 -> 0 | F8: ='Income Statement'!F63 -> 0 | G8: ='Income Statement'!G63 -> 0 | H8: ='Income Statement'!H63 -> 0 | I8: ='Income Statement'!I63 -> 0 | ... M8: ='Income Statement'!M63 -> 0
A28: Solar Cumulative Savings vs. Capital
A29: Month | B29: Jan | C29: Feb | D29: Mar | E29: Apr | F29: May | G29: Jun | H29: Jul | I29: Aug | J29: Sep | K29: Oct | L29: Nov | M29: Dec
A30: Cumulative savings | B30: ='Solar ROI'!B12 -> 0 | C30: ='Solar ROI'!C12 -> 0 | D30: ='Solar ROI'!D12 -> 0 | E30: ='Solar ROI'!E12 -> 0 | F30: ='Solar ROI'!F12 -> 0 | G30: ='Solar ROI'!G12 -> 56 | H30: ='Solar ROI'!H12 -> 157.89 | I30: ='Solar ROI'!I12 -> 344.55 | ... M30: ='Solar ROI'!M12 -> 344.55
A31: Net capital cost (reference) | B31: ='Solar ROI'!$N$7 -> 33318 | C31: ='Solar ROI'!$N$7 -> 33318 | D31: ='Solar ROI'!$N$7 -> 33318 | E31: ='Solar ROI'!$N$7 -> 33318 | F31: ='Solar ROI'!$N$7 -> 33318 | G31: ='Solar ROI'!$N$7 -> 33318 | H31: ='Solar ROI'!$N$7 -> 33318 | I31: ='Solar ROI'!$N$7 -> 33318 | ... M31: ='Solar ROI'!$N$7 -> 33318
A45: Total Assets Trend
A46: Month | B46: Jan | C46: Feb | D46: Mar | E46: Apr | F46: May | G46: Jun | H46: Jul | I46: Aug | J46: Sep | K46: Oct | L46: Nov | M46: Dec
A47: Total assets | B47: =Balances!B17 -> 0 | C47: =Balances!C17 -> 0 | D47: =Balances!D17 -> 0 | E47: =Balances!E17 -> 0 | F47: =Balances!F17 -> 273490.03 | G47: =Balances!G17 -> 26 | H47: =Balances!H17 -> 0 | I47: =Balances!I17 -> 0 | ... M47: =Balances!M17 -> 0

Sheet Imports - Checking
A1: Imports — Checking
A2: Paste Capital One Checking CSV here (full YTD recommended). Run: 📊 Family Finances → Categorize & Roll Up.
A4: Account Number | B4: Transaction Description | C4: Transaction Date | D4: Transaction Type | E4: Transaction Amount | F4: Balance | G4: → Category (auto)

Sheet Imports - Savings
A1: Imports — Savings
A2: Paste Capital One Savings CSV here.
A4: Account Number | B4: Transaction Description | C4: Transaction Date | D4: Transaction Type | E4: Transaction Amount | F4: Balance | G4: → Category (auto)

Sheet Imports - Barclay
A1: Imports — Barclay
A2: Paste Barclaycard CSV (skip header rows above 'Transaction Date').
A4: Transaction Date | B4: Description | C4: Category | D4: Amount | E4: Card Last 4 Digits | F4: Purchased by | G4: → Category (auto)

Sheet Rules
A1: Categorization Rules
A2: Edit to change merchant categorization. First match wins (top down).
A4: Pattern (regex) | B4: Category | C4: Notes
A5: Withdrawal to 360 Performance Savings | B5: __TRANSFER__ | C5: Move $ to savings
A6: Deposit from 360 Performance Savings | B6: __TRANSFER__ | C6: Move $ from savings
A7: Withdrawal to 360 Checking | B7: __TRANSFER__ | C7: Savings → Checking
A8: Deposit from 360 Checking | B8: __TRANSFER__ | C8: Checking → Savings
A9: BARCLAYCARD US CREDITCARD | B9: __TRANSFER__ | C9: Pay Barclaycard bill
A10: TARGET CARD SRVC PAYMENT | B10: __TRANSFER__ | C10: Pay Target card bill
A11: ^Payment Received$ | B11: __TRANSFER__ | C11: Barclaycard side of CC payment
A12: MATHWORKS INC PAYROLL | B12: __INCOME__:Matt | C12: Matt's paycheck
A13: TOWN OF SHARON PAYROLL | B13: __INCOME__:Sue | C13: Sue's paycheck
A14: COMM\. OF MASS\. MASTTAXRFD | B14: __INCOME__:Tax refunds | C14: MA tax refund
A15: Monthly Interest Paid | B15: __INCOME__:Interest | C15: Bank interest
... A20: ROCKET MORTGAGE | B20: __FIXED__:Mortgage | C20: Biweekly mortgage
A21: AMERICAN GEN LIF INS | B21: __FIXED__:Life ins (AmGen)
A22: ALIC INS PREM | B22: __FIXED__:Life ins (ALIC)
A23: TOYOTA ACH | B23: __FIXED__:Car (RAV4) | C23: RAV4 loan
A24: BANK OF AMERICA ONLINE PMT | B24: __FIXED__:Car (Sienna) | C24: Sienna auto loan
A25: VERIZON | B25: __FIXED__:Verizon | C25: Internet
A26: TMOBILE | B26: __FIXED__:T-Mobile | C26: Cell Phone
A27: EVERSOURCE | B27: __FIXED__:Electric
A28: SCHWAB ADV | B28: __FIXED__:Schwab investment
A29: FID BKG SVC | B29: __FIXED__:Fidelity investment
A30: NORTHEASTERN UNI | B30: __FIXED__:Tuition
A31: Check # | B31: __FIXED__:Childcare | C31: Most checks are childcare
A32: ALDI|TRADER JOE|BIG Y|STOP & SHOP|SHAWS|COSTCO WHSE|FARMER IN THE DELL|WARDS BERRY|FLANNEL COW|BUBBLING BROOK|WARD'S BERRY FARM | B32: Groceries
A33: COSTCO GAS|CUMBERLAND FARMS|SHELL OIL|EXXON|BJ.*FUEL|SUNOCO|ROJO CAR WASH|E-ZPASS|GULF OIL 92062891 | B33: Gas / Vehicle
A34: NETFLIX|PARAMOUNT|PEACOCK|NYTIMES|SPOTIFY|PATREON|MISSIONLOCAL|APPLE\.COM/BILL|Groupon|KIRO PRO | B34: Subscriptions
A35: WALPOLE YOUTH|RBI BASEBALL|HOCKOMOCK|PATRIOT FLAG|UNIVERSAL POWER|WALPOLE RECREA|NCAHS|OUTSIDERS MERCHAND|KOHR GOLF|FORE KICKS|SASSAMON TRACE|TOWNECRAFTERS|SP PARK STREET BOOKS | B35: Kids / Activities
A36: COURTYARD|MARRIOTT|SPOTHERO|CAPITOL EXPRESS|SMITH STORE|WIEHLE-RESTON|MR ICEO|PULSEWORKS|BINBOX|^METRO|MULTIPURE|DEERFIELD|LEVY@2NATIONAL|UBER *TRIP | B36: Travel
A37: DYNASTY BARBER|YOO NAILS|VIONIC SHOES|J CREW|NORDSTROM|On Sportswear|POSHMARK|SECOND GLANCE|FRANCISCO SILVA - HAIR|GREAT HAND REFLEXOLOGY | B37: Personal Care
A38: WALGREENS|CVS|PETCO|MUFFIN HOUSE|MUFFIN | B38: Pharmacy / Health
A39: HOME DEPOT|ROCKY.*HARDWARE|DOLLARTREE|HOBBY LOBBY|FIVE BELOW|WALMART|VEVOR|WOODCRAFT 335 | B39: Home / Hardware
A40: SULLIVAN LANDSCAPE | B40: Landscaping
A41: OPC\*US TREASURY|Intuit Inc | B41: __FIXED__:Federal taxes | C41: Annual tax payment
A42: TST\*|DD \*|SQ \*|TACO BELL|MCDONALD|WENDY|CHIPOTLE|DUNKIN|STARBUCKS|CAFE FRESH|PIZZERIA|ELEPHANT|MENCHIES|TESSIES|ANGELS CAFE|GINJO|SLICE\*|MONAHANS|RUSTIC GARDEN|RIBPUBLIC|CITIZEN CRUST|TACO AZUL|PHOBAMI|CHUCK E CHEESE|ESTELLA|EAGLE BROOK|PENANG|BEE SUITE|7-ELEVEN|BOSTON OPERA|YANKEE SPIRITS|TOTAL WINE|LS NORFOLK|CONVENIENCE FOOD|PANERA BREAD #203901 O | B42: Dining out
A43: AMZN|AMAZON | B43: Amazon (misc) | C43: Catch-all Amazon → reconcile on 'Amazon Reconciliation' tab
A44: ATM Withdrawal | B44: Cash / allowances

Sheet Pension - Sue
A1: Sue — MTRS Pension Calculator (Massachusetts Teachers' Retirement System)
A2: Membership Tier 1 confirmed — both 2003 and 2010 predate the 4/2/2012 Tier 2 cutoff. YELLOW = confirm in MyTRS • ORANGE = scenario inputs • Not affiliated with MTRS; verify against the official MTRS estimator before relying on any figure.
A4: ① CONFIRM IN MyTRS (mtrs.state.ma.us)
A5: Effective membership date (year) | B5: 2010 | C5: Confirmed 2010 (refund taken on 2003–07 service, rejoined 2010). Post-2001 join → Tier 1, mandatory R+.
A6: Current creditable service (yrs, today) | B6: 16 | C6: ~16 years (2010 → 2026, continuous). Confirm the exact figure in MyTRS.
A7: RetirementPlus participant? (Y/N) | B7: Y | C7: Auto-YES: joined post-7/1/2001 → mandatory R+ at 11%. A flat 11% on her paystub confirms it.
A8: Years as MTRS teacher (R+ 20-yr test) | B8: 16 | C8: Almost all her creditable service is teacher service; used only for the R+ 20-year test.
A10: ② SCENARIO INPUTS
A11: Sue's current age | B11: 45
A12: Current calendar year | B12: 2026
A13: Current annual salary ($) | B13: 85000 | C13: Enter Sue's actual salary.
A14: Expected annual raise (%) | B14: 0.02
A15: Planned retirement age (scenario) | B15: 60
A16: Buy-back: early years to restore | B16: 0 | C16: If she refunded 2003–07, she can repay to restore ~4–5 yrs. Try 4 to see the effect.
A18: ③ TIER 1 RULES (reference — do not edit) | E18: Age | F18: Factor
A19: Membership tier | B19: Tier 1 | E19: 55 | F19: 0.015
A20: Salary average period | B20: Highest 3 yrs | E20: 56 | F20: 0.016
A21: Maximum benefit cap | B21: 0.8 | E21: 57 | F21: 0.017
A22: R+ enhancement | B22: +2%/yr over 24 yrs | C22: Requires ≥30 yrs creditable, ≥20 as teacher, 11% for 5+ yrs. | E22: 58 | F22: 0.018
A23: Min retirement age (Tier 1) | B23: 55 | E23: 59 | F23: 0.019
E24: 60 | F24: 0.02
A25: ④ RESULT AT PLANNED RETIREMENT AGE | E25: 61 | F25: 0.021
A26: Creditable service at retirement | B26: =B6+(B15-B11)+B16 -> 31 | E26: 62 | F26: 0.022
A27: Age factor at retirement | B27: =IF(B15<55,0,IF(B15>=65,0.025,0.015+(B15-55)*0.001)) -> 0.02 | E27: 63 | F27: 0.023
A28: Salary average (3-yr, est.) $ | B28: =B13*((1+B14)^(B15-B11)+(1+B14)^(B15-B11-1)+(1+B14)^(B15-B11-2))/3 -> 112170.36 | E28: 64 | F28: 0.024
A29: Regular formula benefit % | B29: =MIN($B$21,B27*B26) -> 0.62 | E29: 65 | F29: 0.025
A30: R+ eligible? | B30: =IF(AND($B$7="Y",B26>=30,B8+(B15-B11)>=20),"Yes","No") -> Yes
A31: R+ formula benefit % | B31: =MIN($B$21,B27*B26+0.02*MAX(0,B26-24)) -> 0.76
A32: Applied benefit % | B32: =IF(B30="Yes",B31,B29) -> 0.76
A33: ANNUAL PENSION ($) | B33: =B32*B28 -> 85249.47
A34: Monthly pension ($) | B34: =B33/12 -> 7104.1225
A36: ⑤ PROJECTION BY RETIREMENT AGE (finds the earliest 80% cap)
A37: Retire age | B37: Year | C37: Cred. svc | D37: Age factor | E37: Regular % | F37: R+ elig? | G37: R+ % | H37: Applied % | I37: Annual pension $ | J37: 80% cap?
A38: 55 | B38: =$B$12+(A38-$B$11) -> 2036 | C38: =$B$6+(A38-$B$11)+$B$16 -> 26 | D38: =IF(A38<55,0,IF(A38>=65,0.025,0.015+(A38-55)*0.001)) -> 0.015 | E38: =MIN($B$21,D38*C38) -> 0.39 | F38: =IF(AND($B$7="Y",C38>=30,$B$8+(A38-$B$11)>=20),"Y","N") -> N | G38: =MIN($B$21,D38*C38+0.02*MAX(0,C38-24)) -> 0.43 | H38: =IF(F38="Y",G38,E38) -> 0.39 | I38: =H38*($B$13*((1+$B$14)^(A38-$B$11)+(1+$B$14)^(A38-$B$11-1)+(1+$B$14)^(A38-$B$11-2))/3) -> 39622.497 | J38: =IF(H38>=$B$21,"◄ 80% CAP","")
A39: 56 | B39: =$B$12+(A39-$B$11) -> 2037 | C39: =$B$6+(A39-$B$11)+$B$16 -> 27 | D39: =IF(A39<55,0,IF(A39>=65,0.025,0.015+(A39-55)*0.001)) -> 0.016 | E39: =MIN($B$21,D39*C39) -> 0.432 | F39: =IF(AND($B$7="Y",C39>=30,$B$8+(A39-$B$11)>=20),"Y","N") -> N | G39: =MIN($B$21,D39*C39+0.02*MAX(0,C39-24)) -> 0.492 | H39: =IF(F39="Y",G39,E39) -> 0.432 | I39: =H39*($B$13*((1+$B$14)^(A39-$B$11)+(1+$B$14)^(A39-$B$11-1)+(1+$B$14)^(A39-$B$11-2))/3) -> 44767.326 | J39: =IF(H39>=$B$21,"◄ 80% CAP","")
A40: 57 | B40: =$B$12+(A40-$B$11) -> 2038 | C40: =$B$6+(A40-$B$11)+$B$16 -> 28 | D40: =IF(A40<55,0,IF(A40>=65,0.025,0.015+(A40-55)*0.001)) -> 0.017 | E40: =MIN($B$21,D40*C40) -> 0.476 | F40: =IF(AND($B$7="Y",C40>=30,$B$8+(A40-$B$11)>=20),"Y","N") -> N | G40: =MIN($B$21,D40*C40+0.02*MAX(0,C40-24)) -> 0.556 | H40: =IF(F40="Y",G40,E40) -> 0.476 | I40: =H40*($B$13*((1+$B$14)^(A40-$B$11)+(1+$B$14)^(A40-$B$11-1)+(1+$B$14)^(A40-$B$11-2))/3) -> 50313.501 | J40: =IF(H40>=$B$21,"◄ 80% CAP","")
A41: 58 | B41: =$B$12+(A41-$B$11) -> 2039 | C41: =$B$6+(A41-$B$11)+$B$16 -> 29 | D41: =IF(A41<55,0,IF(A41>=65,0.025,0.015+(A41-55)*0.001)) -> 0.018 | E41: =MIN($B$21,D41*C41) -> 0.522 | F41: =IF(AND($B$7="Y",C41>=30,$B$8+(A41-$B$11)>=20),"Y","N") -> N | G41: =MIN($B$21,D41*C41+0.02*MAX(0,C41-24)) -> 0.622 | H41: =IF(F41="Y",G41,E41) -> 0.522 | I41: =H41*($B$13*((1+$B$14)^(A41-$B$11)+(1+$B$14)^(A41-$B$11-1)+(1+$B$14)^(A41-$B$11-2))/3) -> 56279.244 | J41: =IF(H41>=$B$21,"◄ 80% CAP","")
A42: 59 | B42: =$B$12+(A42-$B$11) -> 2040 | C42: =$B$6+(A42-$B$11)+$B$16 -> 30 | D42: =IF(A42<55,0,IF(A42>=65,0.025,0.015+(A42-55)*0.001)) -> 0.019 | E42: =MIN($B$21,D42*C42) -> 0.57 | F42: =IF(AND($B$7="Y",C42>=30,$B$8+(A42-$B$11)>=20),"Y","N") -> Y | G42: =MIN($B$21,D42*C42+0.02*MAX(0,C42-24)) -> 0.69 | H42: =IF(F42="Y",G42,E42) -> 0.69 | I42: =H42*($B$13*((1+$B$14)^(A42-$B$11)+(1+$B$14)^(A42-$B$11-1)+(1+$B$14)^(A42-$B$11-2))/3) -> 75879.947 | J42: =IF(H42>=$B$21,"◄ 80% CAP","")
A43: 60 | B43: =$B$12+(A43-$B$11) -> 2041 | C43: =$B$6+(A43-$B$11)+$B$16 -> 31 | D43: =IF(A43<55,0,IF(A43>=65,0.025,0.015+(A43-55)*0.001)) -> 0.02 | E43: =MIN($B$21,D43*C43) -> 0.62 | F43: =IF(AND($B$7="Y",C43>=30,$B$8+(A43-$B$11)>=20),"Y","N") -> Y | G43: =MIN($B$21,D43*C43+0.02*MAX(0,C43-24)) -> 0.76 | H43: =IF(F43="Y",G43,E43) -> 0.76 | I43: =H43*($B$13*((1+$B$14)^(A43-$B$11)+(1+$B$14)^(A43-$B$11-1)+(1+$B$14)^(A43-$B$11-2))/3) -> 85249.47 | J43: =IF(H43>=$B$21,"◄ 80% CAP","")
A44: 61 | B44: =$B$12+(A44-$B$11) -> 2042 | C44: =$B$6+(A44-$B$11)+$B$16 -> 32 | D44: =IF(A44<55,0,IF(A44>=65,0.025,0.015+(A44-55)*0.001)) -> 0.021 | E44: =MIN($B$21,D44*C44) -> 0.672 | F44: =IF(AND($B$7="Y",C44>=30,$B$8+(A44-$B$11)>=20),"Y","N") -> Y | G44: =MIN($B$21,D44*C44+0.02*MAX(0,C44-24)) -> 0.8 | H44: =IF(F44="Y",G44,E44) -> 0.8 | I44: =H44*($B$13*((1+$B$14)^(A44-$B$11)+(1+$B$14)^(A44-$B$11-1)+(1+$B$14)^(A44-$B$11-2))/3) -> 91531.01 | J44: =IF(H44>=$B$21,"◄ 80% CAP","") -> ◄ 80% CAP
...

Sheet FIRE Dashboard
A1: FIRE Dashboard — Naughton Family
A2: Educational planning tool, not investment advice. ORANGE = assumptions you set • YELLOW = balances/contributions (snapshot as of now — update over time). FI math uses a REAL (inflation-adjusted) return.
A4: ① HOUSEHOLD ASSUMPTIONS
A5: Matt's current age | B5: 45
A6: Sue's current age | B6: 45
A7: Current calendar year | B7: 2026
A8: Target annual retirement spend ($) | B8: 90000 | C8: Use your Income Statement expenses as a guide.
A9: Safe withdrawal rate (SWR) | B9: 0.04
A10: Nominal expected return | B10: 0.07 | C10: Matches the 7% on your Scenarios tab.
A11: Assumed inflation | B11: 0.03
A12: Real return (auto) | B12: =(1+B10)/(1+B11)-1 -> 0.038834951
A14: ② CURRENT INVESTED ASSETS (from Balances)
A15: Matt 401k (MathWorks) | B15: 228000
A16: Sue 403b (Equitable) | B16: 0
A17: IRAs (Matt + Sue) | B17: 0
A18: HSA (invested portion) | B18: 0
A19: Taxable brokerage (Schwab) | B19: 0
A20: Cash earmarked for FI | B20: 0 | C20: Exclude your emergency fund.
A21: TOTAL INVESTED | B21: =SUM(B15:B20) -> 228000
A22: (memo) 529 — excluded from FI | B22: 14298 | C22: Kids' college — not part of your FI number.
A24: ③ ANNUAL CONTRIBUTIONS
A25: Matt 401k (employee) | B25: 23500
A26: Employer 401k match | B26: 4338
A27: Sue 403b | B27: 0
A28: HSA | B28: 9000 | C28: 2027 family HSA limit.
A29: IRAs (both) | B29: 15000
A30: Taxable brokerage | B30: 0
A31: 529 | B31: 1200
A32: TOTAL ANNUAL INVESTED | B32: =SUM(B25:B31) -> 53038
A34: ④ SAVINGS RATE
A35: Gross household income ($) | B35: 229000 | C35: Matt (~$144k) + Sue's salary.
A36: Savings rate | B36: =B32/B35 -> 0.23160699
A38: ⑤ FI NUMBER (with & without the pension)
A39: Gross FI number (spend ÷ SWR) | B39: =B8/B9 -> 2250000 | C39: Portfolio-only target, today's dollars — the conservative number to aim at.
A40: Sue's annual pension (from Pension tab) | B40: ='Pension - Sue'!B33 -> 85249.47 | C40: Future nominal $ (grown to her retirement) — treat the offset below as approximate.
A41: Social Security household (annual, est) | B41: 40000 | C41: WEP/GPO repealed (2025) — Sue keeps full spousal/survivor SS. Verify her record.
A42: Income floor (pension + SS) | B42: =B40+B41 -> 125249.47
A43: Pension+SS capitalized value | B43: =B42/B9 -> 3131236.8 | C43: Roughly what that income floor is 'worth' vs a portfolio — it reduces the target below.
A44: NET FI number (target once floor starts) | B44: =MAX(0,(B8-B42)/B9) -> 0 | C44: $0 means pension+SS alone cover target spend in the traditional-retirement phase.
A48: ⑥ YEARS TO FI (portfolio-only runway)
...

Sheet Amazon Reconciliation
A1: Amazon — Monthly Reconciliation
A2: All Amazon spend now lands in ONE bucket — 'Amazon (misc)', CC Detail row 14 — via a single regex rule (AMZN|AMAZON). Each month, split that total into real categories below. ORANGE = you enter $. The reference list at the bottom shows the actual Amazon transactions to guide the split.
A4: ① AMAZON TOTAL TO RECONCILE (auto — from CC Detail)
A5: Month | B5: Jan | C5: Feb | D5: Mar | E5: Apr | F5: May | G5: Jun | H5: Jul | I5: Aug | J5: Sep | K5: Oct | L5: Nov | M5: Dec | N5: YTD
A6: Amazon (misc) — to reconcile | B6: ='CC Detail'!B14 -> 856.77 | C6: ='CC Detail'!C14 -> 267.06 | D6: ='CC Detail'!D14 -> 417.23 | E6: ='CC Detail'!E14 -> 482.16 | F6: ='CC Detail'!F14 -> 688.51 | G6: ='CC Detail'!G14 -> 157.93 | H6: ='CC Detail'!H14 -> 0 | I6: ='CC Detail'!I14 -> 0 | ... M6: ='CC Detail'!M14 -> 0 | N6: =SUM(B6:M6) -> 2869.66
A8: ② ALLOCATE INTO CATEGORIES (enter $ per month)
A9: Category | B9: Jan | C9: Feb | D9: Mar | E9: Apr | F9: May | G9: Jun | H9: Jul | I9: Aug | J9: Sep | K9: Oct | L9: Nov | M9: Dec | N9: YTD
A10: Groceries | B10: 0 | C10: 0 | D10: 0 | E10: 0 | F10: 0 | G10: 0 | H10: 0 | I10: 0 | J10: 0 | K10: 0 | L10: 0 | M10: 0 | N10: =SUM(B10:M10) -> 0
A11: Kids / Activities | B11: 0 | C11: 0 | D11: 0 | E11: 0 | F11: 0 | G11: 0 | H11: 0 | I11: 0 | J11: 0 | K11: 0 | L11: 0 | M11: 0 | N11: =SUM(B11:M11) -> 0
A12: Personal Care | B12: 0 | C12: 0 | D12: 0 | E12: 0 | F12: 0 | G12: 0 | H12: 0 | I12: 0 | J12: 0 | K12: 0 | L12: 0 | M12: 0 | N12: =SUM(B12:M12) -> 0
A13: Pharmacy / Health | B13: 0 | C13: 0 | D13: 0 | E13: 0 | F13: 0 | G13: 0 | H13: 0 | I13: 0 | J13: 0 | K13: 0 | L13: 0 | M13: 0 | N13: =SUM(B13:M13) -> 0
A14: Home / Hardware | B14: 0 | C14: 0 | D14: 0 | E14: 0 | F14: 0 | G14: 0 | H14: 0 | I14: 0 | J14: 0 | K14: 0 | L14: 0 | M14: 0 | N14: =SUM(B14:M14) -> 0
A15: Subscriptions (Prime/Kindle/Audible) | B15: 0 | C15: 0 | D15: 0 | E15: 0 | F15: 0 | G15: 0 | H15: 0 | I15: 0 | J15: 0 | K15: 0 | L15: 0 | M15: 0 | N15: =SUM(B15:M15) -> 0
A16: Other / gifts | B16: 0 | C16: 0 | D16: 0 | E16: 0 | F16: 0 | G16: 0 | H16: 0 | I16: 0 | J16: 0 | K16: 0 | L16: 0 | M16: 0 | N16: =SUM(B16:M16) -> 0
A17: Allocated total | B17: =SUM(B10:B16) -> 0 | C17: =SUM(C10:C16) -> 0 | D17: =SUM(D10:D16) -> 0 | E17: =SUM(E10:E16) -> 0 | F17: =SUM(F10:F16) -> 0 | G17: =SUM(G10:G16) -> 0 | H17: =SUM(H10:H16) -> 0 | I17: =SUM(I10:I16) -> 0 | ... N17: =SUM(N10:N16) -> 0
A18: Unallocated remaining | B18: =B6-B17 -> 856.77 | C18: =C6-C17 -> 267.06 | D18: =D6-D17 -> 417.23 | E18: =E6-E17 -> 482.16 | F18: =F6-F17 -> 688.51 | G18: =G6-G17 -> 157.93 | H18: =H6-H17 -> 0 | I18: =I6-I17 -> 0 | ... N18: =N6-N17 -> 2869.66
A20: ③ RECONCILED CATEGORY TOTALS (YTD) — the un-muddied picture
A21: Category | B21: Native (CC Detail) | C21: + Amazon
A22: Groceries | B22: ='CC Detail'!N5 -> 3800.52 | C22: =N10 -> 0 | D22: =B22+C22 -> 3800.52
A23: Kids / Activities | B23: ='CC Detail'!N9 -> 1912.54 | C23: =N11 -> 0 | D23: =B23+C23 -> 1912.54
A24: Personal Care | B24: ='CC Detail'!N11 -> 802.44 | C24: =N12 -> 0 | D24: =B24+C24 -> 802.44
A25: Pharmacy / Health | B25: ='CC Detail'!N12 -> 233.48 | C25: =N13 -> 0 | D25: =B25+C25 -> 233.48
A26: Home / Hardware | B26: ='CC Detail'!N13 -> 997.53 | C26: =N14 -> 0 | D26: =B26+C26 -> 997.53
A27: Subscriptions | B27: ='CC Detail'!N8 -> 647.59 | C27: =N15 -> 0 | D27: =B27+C27 -> 647.59
A28: Other / gifts | B28: ='CC Detail'!N17 -> 32920.35 | C28: =N16 -> 0 | D28: =B28+C28 -> 32920.35
A29: Note: once split, these 'true totals' show real spend per category — Amazon no longer hides hardware, hygiene, and kids' purchases in one lump. Feed these into the guardrail when it's built.
A32: ④ REFERENCE — current Amazon transactions (auto, read-only)
A33: Pulls Amazon rows from your Barclay import so you can see what to split. Refreshes when you paste new data.
A34: Date | B34: Description | C34: Amount | D34: Purchased by

Sheet Solar Reinvestment
A1: Solar — Reinvestment & Effective ROI
A2: Goal: redirect your former electric-bill spend into a growth vehicle so the solar's ROI compounds. ORANGE = inputs. Enphase has no CSV export, so enter the monthly energy log by hand (you can backfill Mar–Sep now, then add one row per month). Educational planning, not investment/tax advice.
A4: ① INCENTIVES & NET CAPITAL COST
A5: Gross capital outlay | B5: ='Solar ROI'!N5 -> 33318
A6: Federal ITC (25D) | B6: 0 | C6: $0 if placed in service in 2026 (OBBB ended 25D after 12/31/2025). If PTO by 12/31/2025, use ~0.30×gross.
A7: MA state credit (15%, max $1,000) | B7: =MIN(1000,0.15*B5) -> 1000
A8: Other rebates / utility | B8: 0
A9: NET CAPITAL COST | B9: =B5-B6-B7-B8 -> 32318
A11: ② MONTHLY ENERGY LOG (Enphase — manual entry, kWh)
A12: Enter each month from your Enphase report. Net export = Exported − Imported (auto).
A13: Month | B13: Produced | C13: Consumed | D13: Imported | E13: Exported | F13: Net export
A14: Jan | F14: =E14-D14 -> 0
A15: Feb | F15: =E15-D15 -> 0
A16: Mar | B16: 133.1 | C16: 661.4 | D16: 528.3 | E16: 0 | F16: =E16-D16 -> -528.3
A17: Apr | B17: 314.2 | C17: 102.6 | D17: 50.1 | E17: 261.7 | F17: =E17-D17 -> 211.6
A18: May | B18: 997.1 | C18: 475.1 | D18: 246.7 | E18: 768.7 | F18: =E18-D18 -> 522
A19: Jun | B19: 1128.1 | C19: 784.5 | D19: 383 | E19: 726.6 | F19: =E19-D19 -> 343.6
A20: Jul | B20: 1058.5 | C20: 964.6 | D20: 507.4 | E20: 601.3 | F20: =E20-D20 -> 93.9
A21: Aug | B21: 919.3 | C21: 938.4 | D21: 531.1 | E21: 512 | F21: =E21-D21 -> -19.1
A22: Sep | F22: =E22-D22 -> 0
A23: Oct | F23: =E23-D23 -> 0
A24: Nov | F24: =E24-D24 -> 0
A25: Dec | F25: =E25-D25 -> 0
A26: Total | B26: =SUM(B14:B25) -> 4550.3 | C26: =SUM(C14:C25) -> 3926.6 | D26: =SUM(D14:D25) -> 2246.6 | E26: =SUM(E14:E25) -> 2870.3 | F26: =SUM(F14:F25) -> 623.7
A27: Enter each month from your Enphase monthly report (no CSV export — read the tile values). Production swings seasonally: March is pre-filled from your report (133 kWh produced vs 661 consumed → net import), while summer months over-produce and export. Net export = Exported − Imported (negative = net import).
A30: ③ SAVINGS TO REINVEST
A31: Pre-solar baseline bill ($/mo) | B31: 166 | C31: 2025 average actual electric bill (real data: $1,988/yr ÷ 12).
A32: Post-solar actual bill ($/mo) | B32: 95 | C32: Est. full-year post-solar avg (summer bills $87–122; winter eased by banked net-metering credits). Preliminary — refine after a full post-solar year.
A33: Monthly avoided cost (reinvest) | B33: =MAX(0,B31-B32) -> 71
A34: Annual avoided cost | B34: =B33*12 -> 852
A35: SMART incentive ($/kWh) | B35: 0.03
A36: Est. annual production (kWh) | B36: 7000 | C36: Rough full-year estimate from your 2026 trajectory (YTD ~5 MWh by Aug). Refine after a full year.
A37: Annual SMART payment (yrs 1–10) | B37: =B35*B36 -> 210
A38: Blended electric rate ($/kWh) | B38: 0.3 | C38: Used to value net-metering credits from exports.
A40: ④ REINVESTMENT MODEL — accelerate the ROI
A41: Reinvestment return (nominal) | B41: 0.07 | C41: Matches the 7% on your Scenarios tab.
A42: Electric rate escalation (%/yr) | B42: 0.04
A43: Horizon (years) | B43: 25
A44: First full year | B44: 2026
A46: Year | B46: Calendar | C46: Avoided cost | D46: SMART | E46: Reinvested/yr | F46: Reinvested bal. | G46: Simple cum. | H46: Status
...

Sheet HSA Election Planner
A1: HSA Election Planner — November open enrollment
A2: Turns your freed-up cash (solar + mobile + old FSA) into a concrete HSA election for the 2027 plan year. ORANGE = inputs. Educational planning, not tax advice.
A4: ① 2027 HSA LIMIT
A5: Coverage type | B5: Family
A6: 2027 HSA limit (family) | B6: 9000 | C6: Self-only 2027 = $4,500. Family = $9,000.
A7: Catch-up (age 55+, each) | B7: 0 | C7: You're 45 — the +$1,000 each starts in 2036.
A8: Employer HSA seed/contribution | B8: 0 | C8: If MathWorks seeds the HSA, it counts against the limit — enter it.
A9: Your max employee election | B9: =B6+B7-B8 -> 9000
A10: Pay periods / year | B10: 26 | C10: MathWorks is biweekly = 26.
A11: Max per paycheck | B11: =B9/B10 -> 346.15385
A13: ② FREED-UP CASH TO REDIRECT (annual)
A14: Solar avoided cost (from Solar tab) | B14: ='Solar Reinvestment'!B34 -> 852
A15: Mobile / phone savings | B15: 600 | C15: From switching to the cheaper carrier.
A16: Former FSA Health Care contribution | B16: 2500 | C16: What you were putting in the FSA (~$96/pay × 26). This moves to the HSA.
A17: Other freed cash | B17: 0
A18: TOTAL new annual money | B18: =SUM(B14:B17) -> 3952
A20: ③ ELECTION PLAN
A21: Suggested election (fund HSA from freed cash) | B21: =MIN(B9,B18) -> 3952 | C21: Fund the more tax-efficient HSA first, up to the limit.
A22: Your chosen HSA election | B22: =B21 -> 3952 | C22: Override with the number you actually elect.
A23: → Per paycheck | B23: =B22/B10 -> 152
A24: → % of family limit used | B24: =B22/B6 -> 0.43911111
A25: Remaining freed cash → IRAs | B25: =MAX(0,B18-B22) -> 0
A26: Extra needed to hit $9,000 max | B26: =MAX(0,B9-B18) -> 5048 | C26: Shortfall between freed cash and a full max — pull from elsewhere if you want to top out.
A28: ④ DECISION NOTES (from our planning)
A29: • HSA is the most tax-efficient bucket (triple advantage + the payroll-tax break) — fund it first from freed cash, then overflow to IRAs.
A30: • Orthodontia: pay out of pocket, save every receipt, let the HSA stay invested and reimburse yourself later (the 'shoebox' growth play).
A31: • Open + fund the HSA (even $1) BEFORE the first ortho expense — expenses incurred before the account exists can never be reimbursed.
A32: • Confirm your 2026 FSA has no carryover/grace period bleeding into 2027 — it can block HSA eligibility early in the year. Consider a limited-purpose (dental/vision) FSA.
A33: • 2027 IRA limit isn't official yet (~$7,500 each expected); confirm in November before finalizing the IRA split.

Sheet Monthly Entry
A1: Monthly Entry — one place to update everything
A2: Pick the month, fill in what you have (blanks are skipped), then run 📊 Family Finances → Post Monthly Entry. Values fan out to Balances, Solar, Amazon Reconciliation and Comp & Benefits. You can also fill this from your phone via the linked Google Form.
A4: Month to post | B4: Sep | C4: Choose the month these figures belong to.
A5: Data as of (date) | C5: Optional — for your records.
A6: ① ACCOUNT BALANCES (month-end)
A7: Capital One Checking | C7: → Balances
A8: Capital One Savings
A9: Venmo float
A10: Fidelity Money Market
A11: Schwab investment
A12: 529
A13: FSA Dep Care balance
A14: FSA Health Care balance
A15: Matt 401k
A16: Sue 403b
A17: Sue pension (est.)
A18: Other
A20: ② SOLAR — ENERGY (Enphase, kWh)
A21: Produced (kWh) | C21: → Solar Reinvestment log
A22: Consumed (kWh)
A23: Imported (kWh)
A24: Exported (kWh)
A25: ③ SOLAR — ELECTRIC BILL
A26: Baseline electric (would-have-paid) | C26: → Solar ROI row 9
A27: Actual electric bill | C27: → Solar ROI row 10
A29: ④ AMAZON — split this month's total into buckets
A30: Amazon total to split (auto) | B30: =IFERROR(INDEX('CC Detail'!B14:M14,MATCH($B$4,{"Jan","Feb","Mar","Apr","May","Jun","Jul","Aug","Sep","Oct","Nov","Dec"},0)),"") -> 0 | C30: Pulled from CC Detail for the chosen month — split it below.
A31: Groceries | C31: → Amazon Reconciliation
A32: Kids / Activities
A33: Personal Care
A34: Pharmacy / Health
A35: Home / Hardware
A36: Subscriptions
A37: Other / gifts
A38: Split check (should match total) | B38: =SUM(B31:B37) -> 0 | C38: Compare to Amazon total above.
A40: ⑤ COMP & BENEFITS (YTD, from paystub)
A41: Matt gross earnings YTD | C41: → Comp & Benefits
A42: Matt 401k contribution YTD
A43: Matt 401k match YTD
A44: FSA Dep Care YTD
...

Sheet Spending Guardrail
A1: Discretionary Spending Guardrail
A2: Three lanes — Matt, Sue, Household — for dinners, drinks, coffee, entertainment, convenience & vices. Unused budget ROLLS OVER, so a high 'available' balance = green light to splurge; a negative one = pause. ORANGE = inputs (actuals arrive via Monthly Entry). Educational tool, not advice.
A4: ① BUDGET CONFIG (per month)
A5: Matt monthly budget | B5: 200
A6: Sue monthly budget | B6: 200
A7: Household monthly budget | B7: 300 | C7: Shared dinners/entertainment together — set to taste.
A8: Combined monthly budget | B8: =B5+B6+B7 -> 700
A9: Splurge-room threshold ($) | B9: 150 | C9: When a lane's rollover balance clears this, it's green to splurge.
A10: Reporting month | B10: Sep | C10: Drives the standings panel below.
A12: ② WHERE YOU STAND (reporting month)
A13: Lane | B13: Budget | C13: Spent (mo) | D13: Rollover avail. | E13: Verdict
A14: Matt | B14: =B5 -> 200 | C14: =INDEX(B22:M22,MATCH($B$10,{"Jan","Feb","Mar","Apr","May","Jun","Jul","Aug","Sep","Oct","Nov","Dec"},0)) -> 0 | D14: =INDEX(B23:M23,MATCH($B$10,{"Jan","Feb","Mar","Apr","May","Jun","Jul","Aug","Sep","Oct","Nov","Dec"},0)) -> 1800 | E14: =IF(D14="","",IF(D14<0,"🔴 over — pause",IF(D14>=$B$9,"🟢 splurge OK","🟡 on track"))) -> 🟢 splurge OK
A15: Sue | B15: =B6 -> 200 | C15: =INDEX(B25:M25,MATCH($B$10,{"Jan","Feb","Mar","Apr","May","Jun","Jul","Aug","Sep","Oct","Nov","Dec"},0)) -> 0 | D15: =INDEX(B26:M26,MATCH($B$10,{"Jan","Feb","Mar","Apr","May","Jun","Jul","Aug","Sep","Oct","Nov","Dec"},0)) -> 1800 | E15: =IF(D15="","",IF(D15<0,"🔴 over — pause",IF(D15>=$B$9,"🟢 splurge OK","🟡 on track"))) -> 🟢 splurge OK
A16: Household | B16: =B7 -> 300 | C16: =INDEX(B28:M28,MATCH($B$10,{"Jan","Feb","Mar","Apr","May","Jun","Jul","Aug","Sep","Oct","Nov","Dec"},0)) -> 0 | D16: =INDEX(B29:M29,MATCH($B$10,{"Jan","Feb","Mar","Apr","May","Jun","Jul","Aug","Sep","Oct","Nov","Dec"},0)) -> 2700 | E16: =IF(D16="","",IF(D16<0,"🔴 over — pause",IF(D16>=$B$9,"🟢 splurge OK","🟡 on track"))) -> 🟢 splurge OK
A17: Combined | B17: =B8 -> 700 | C17: =INDEX(B30:M30,MATCH($B$10,{"Jan","Feb","Mar","Apr","May","Jun","Jul","Aug","Sep","Oct","Nov","Dec"},0)) -> 0 | D17: =INDEX(B32:M32,MATCH($B$10,{"Jan","Feb","Mar","Apr","May","Jun","Jul","Aug","Sep","Oct","Nov","Dec"},0)) -> 6300 | E17: =IF(D17="","",IF(D17<0,"🔴 over — pause",IF(D17>=$B$9,"🟢 splurge OK","🟡 on track"))) -> 🟢 splurge OK
A19: ③ MONTHLY TRACKER (rollover carries forward)
B20: Jan | C20: Feb | D20: Mar | E20: Apr | F20: May | G20: Jun | H20: Jul | I20: Aug | J20: Sep | K20: Oct | L20: Nov | M20: Dec | N20: YTD
A21: Matt — Budget | B21: =$B$5 -> 200 | C21: =$B$5 -> 200 | D21: =$B$5 -> 200 | E21: =$B$5 -> 200 | F21: =$B$5 -> 200 | G21: =$B$5 -> 200 | H21: =$B$5 -> 200 | I21: =$B$5 -> 200 | ... M21: =$B$5 -> 200 | N21: =SUM(B21:M21) -> 2400
A22: Matt — Actual (spent) | N22: =SUM(B22:M22) -> 0
A23: Matt — Rollover available | B23: =B21-B22 -> 200 | C23: =B23+C21-C22 -> 400 | D23: =C23+D21-D22 -> 600 | E23: =D23+E21-E22 -> 800 | F23: =E23+F21-F22 -> 1000 | G23: =F23+G21-G22 -> 1200 | H23: =G23+H21-H22 -> 1400 | I23: =H23+I21-I22 -> 1600 | J23: =I23+J21-J22 -> 1800 | ... M23: =L23+M21-M22 -> 2400 | N23: =M23 -> 2400
A24: Sue — Budget | B24: =$B$6 -> 200 | C24: =$B$6 -> 200 | D24: =$B$6 -> 200 | E24: =$B$6 -> 200 | F24: =$B$6 -> 200 | G24: =$B$6 -> 200 | H24: =$B$6 -> 200 | I24: =$B$6 -> 200 | ... M24: =$B$6 -> 200 | N24: =SUM(B24:M24) -> 2400
A25: Sue — Actual (spent) | N25: =SUM(B25:M25) -> 0
A26: Sue — Rollover available | B26: =B24-B25 -> 200 | C26: =B26+C24-C25 -> 400 | D26: =C26+D24-D25 -> 600 | E26: =D26+E24-E25 -> 800 | F26: =E26+F24-F25 -> 1000 | G26: =F26+G24-G25 -> 1200 | H26: =G26+H24-H25 -> 1400 | I26: =H26+I24-I25 -> 1600 | J26: =I26+J24-J25 -> 1800 | ... M26: =L26+M24-M25 -> 2400 | N26: =M26 -> 2400
A27: Household — Budget | B27: =$B$7 -> 300 | C27: =$B$7 -> 300 | D27: =$B$7 -> 300 | E27: =$B$7 -> 300 | F27: =$B$7 -> 300 | G27: =$B$7 -> 300 | H27: =$B$7 -> 300 | I27: =$B$7 -> 300 | ... M27: =$B$7 -> 300 | N27: =SUM(B27:M27) -> 3600
A28: Household — Actual (spent) | N28: =SUM(B28:M28) -> 0
A29: Household — Rollover available | B29: =B27-B28 -> 300 | C29: =B29+C27-C28 -> 600 | D29: =C29+D27-D28 -> 900 | E29: =D29+E27-E28 -> 1200 | F29: =E29+F27-F28 -> 1500 | G29: =F29+G27-G28 -> 1800 | H29: =G29+H27-H28 -> 2100 | I29: =H29+I27-I28 -> 2400 | J29: =I29+J27-J28 -> 2700 | ... M29: =L29+M27-M28 -> 3600 | N29: =M29 -> 3600
A30: Combined — Actual | B30: =B22+B25+B28 -> 0 | C30: =C22+C25+C28 -> 0 | D30: =D22+D25+D28 -> 0 | E30: =E22+E25+E28 -> 0 | F30: =F22+F25+F28 -> 0 | G30: =G22+G25+G28 -> 0 | H30: =H22+H25+H28 -> 0 | I30: =I22+I25+I28 -> 0 | ... M30: =M22+M25+M28 -> 0 | N30: =SUM(B30:M30) -> 0
A31: Combined — Budget | B31: =B21+B24+B27 -> 700 | C31: =C21+C24+C27 -> 700 | D31: =D21+D24+D27 -> 700 | E31: =E21+E24+E27 -> 700 | F31: =F21+F24+F27 -> 700 | G31: =G21+G24+G27 -> 700 | H31: =H21+H24+H27 -> 700 | I31: =I21+I24+I27 -> 700 | ... M31: =M21+M24+M27 -> 700 | N31: =SUM(B31:M31) -> 8400
A32: Combined — Rollover available | B32: =B23+B26+B29 -> 700 | C32: =C23+C26+C29 -> 1400 | D32: =D23+D26+D29 -> 2100 | E32: =E23+E26+E29 -> 2800 | F32: =F23+F26+F29 -> 3500 | G32: =G23+G26+G29 -> 4200 | H32: =H23+H26+H29 -> 4900 | I32: =I23+I26+I29 -> 5600 | ... M32: =M23+M26+M29 -> 8400 | N32: =M32 -> 8400
A34: ④ IMPACT ON YOUR SAVINGS / FIRE
A35: YTD combined budget | B35: =N31 -> 8400
A36: YTD combined actual | B36: =N30 -> 0
A37: YTD over / (under) | B37: =N30-N31 -> -8400 | C37: Positive = overspent (money that didn't get invested).
A38: Growth factor (real, 20 yrs) | B38: =(1+'FIRE Dashboard'!B12)^20 -> 2.1425505
A39: Compounded cost of overspend | B39: =MAX(0,B37)*B38 -> 0 | C39: What this year's overspend would be worth in 20 yrs if invested instead.
A41: How rollover works: each month adds the lane's budget and subtracts what you spent. Underspend and the balance grows (bank it for a guilt-free splurge later); overspend and it goes negative until you claw it back. Actuals post automatically from the Monthly Entry tab.
